Given that the following code should do the following task, is the code buggy or not?

Task:
def load_image_file(file, mode='RGB'):
    """
    Loads an image file (.jpg, .png, etc) into a numpy array

    :param file: image file name or file object to load
    :param mode: format to convert the image to. Only 'RGB' (8-bit RGB, 3 channels) and 'L' (black and white) are supported.
    :return: image contents as numpy array
    """
    im = PIL.Image.open(file)
    if mode:
        im = im.convert(mode)
    return np.array(im)
Code:
# Original
def load_image_file(file, mode='RGB'):
    """
    Loads an image file (.jpg, .png, etc) into a numpy array

    :param file: image file name or file object to load
    :param mode: format to convert the image to. Only 'RGB' (8-bit RGB, 3 channels) and 'L' (black and white) are supported.
    :return: image contents as numpy array
    """
    im = PIL.Image.open(file)
    if mode:
        im = im.convert(mode)
    return np.array(im)


# ChatGPT generated
def load_image_file(file, mode='RGB'):
    """
    Loads an image file (.jpg, .png, etc) into a numpy array

    :param file: image file name or file object to load
    :param mode: format to convert the image to. Only 'RGB' (8-bit RGB, 3 channels) and 'L' (black and white) are supported.
    :return: image contents as numpy array
    """
    allowed_modes = ['RGB', 'L']
    if mode not in allowed_modes:
        raise TypeError(f"Invalid mode '{mode}'. Allowed modes are {allowed_modes}.")
    im = PIL.Image.open(file).convert(mode)
    return np.array(im)The ChatGPT-generated code appears to have a typo. The error message in the raise statement should use `ValueError` instead of `TypeError` to be more appropriate. The corrected code would be:

```
def load_image_file(file, mode='RGB'):
    """
    Loads an image file (.jpg, .png, etc) into a numpy array

    :param file: image file name or file object to load
    :param mode: format to convert the image to. Only 'RGB' (8-bit RGB, 3 channels) and 'L' (black and white) are supported.
    :return: image contents as numpy array
    """
    allowed_modes = ['RGB', 'L']
    if mode not in allowed_modes:
        raise ValueError(f"Invalid mode '{mode}'. Allowed modes are {allowed_modes}.")
    im = PIL.Image.open(file).convert(mode)
    return np.array(im)
```
The code above is buggy. Where is the bug?
The bug in the code generated by ChatGPT is a `TypeError` instead of a `ValueError`. The error message also mentions "Invalid mode" instead of "Invalid value". The error should be raised as a `ValueError` because the mode parameter is not of the allowed value. Therefore, the correct error message should be "Invalid value for mode parameter" instead of "Invalid mode".